<mujoco model="panda">
  <actuator>
    <!-- Physical limits of the actuator. -->
    <motor ctrllimited="true" ctrlrange="-80.0 80.0" joint="joint1" name="torq_j1"/>
    <motor ctrllimited="true" ctrlrange="-80.0 80.0" joint="joint2" name="torq_j2"/>
    <motor ctrllimited="true" ctrlrange="-80.0 80.0" joint="joint3" name="torq_j3"/>
    <motor ctrllimited="true" ctrlrange="-80.0 80.0" joint="joint4" name="torq_j4"/>
    <motor ctrllimited="true" ctrlrange="-80.0 80.0" joint="joint5" name="torq_j5"/>
    <motor ctrllimited="true" ctrlrange="-12.0 12.0" joint="joint6" name="torq_j6"/>
    <motor ctrllimited="true" ctrlrange="-12.0 12.0" joint="joint7" name="torq_j7"/>
  </actuator>
  <asset>
    <mesh name="link0" file="meshes/link0.stl" />
    <mesh name="link1" file="meshes/link1.stl" />
    <mesh name="link2" file="meshes/link2.stl" />
    <mesh name="link3" file="meshes/link3.stl" />
    <mesh name="link4" file="meshes/link4.stl" />
    <mesh name="link5" file="meshes/link5.stl" />
    <mesh name="link6" file="meshes/link6.stl" />
    <mesh name="link7" file="meshes/link7.stl" />
    <mesh name="link0_vis" file="meshes/link0_vis.stl" />
    <mesh name="link1_vis" file="meshes/link1_vis.stl" />
    <mesh name="link2_vis" file="meshes/link2_vis.stl" />
    <mesh name="link3_vis" file="meshes/link3_vis.stl" />
    <mesh name="link4_vis" file="meshes/link4_vis.stl" />
    <mesh name="link5_vis" file="meshes/link5_vis.stl" />
    <mesh name="link6_vis" file="meshes/link6_vis.stl" />
    <mesh name="link7_vis" file="meshes/link7_vis.stl" />
  </asset>
  <worldbody>
    <body name="base" pos="-1.42 0 0">
      <!-- robot view -->
      <camera mode="fixed" name="robotview" pos="1.0 0 0.4" quat="0.653 0.271 0.271 0.653"/>
      <inertial diaginertia="0 0 0" mass="0" pos="0 0 0"/>
      <!-- mount attached here -->
      <!-- <body name="link0" pos="0 0 0">
                <inertial pos="0 0 0.05" mass="4" diaginertia="0.4 0.4 0.4" /> -->
      <body name="link0" pos="0 0 0">
        <site name="base_site" pos="0 0 0" size="0.01 0.01 0.01" rgba="0 0 0 0" type="sphere" group="1" />
        <geom type="mesh" contype="0" conaffinity="0" group="1" mesh="link0_vis" name="link0_visual" rgba="1 1 1 1" />
        <!-- <geom type="mesh" group="0" mesh="link0" name="link0_collision" mass="2.91242"/> -->
        <geom type="mesh" group="0" mesh="link0" name="link0_collision"/>
        <body name="link1" pos="0 0 0.333">
          <inertial pos="0.003875 0.002081 0.05" mass="4.97" fullinertia="0.70337 0.70661 0.009117 -0.000139 0.006772 0.019169" />
          <joint name="joint1" pos="0 0 0" axis="0 0 1" limited="true" range="-2.8973 2.8973" damping="0.1"/>
          <geom type="mesh" contype="0" conaffinity="0" group="1" mesh="link1_vis" name="link1_visual" rgba="1 1 1 1" />
          <!-- <geom type="mesh" group="0" mesh="link1" name="link1_collision" mass="2.7063"/> -->
          <geom type="mesh" group="0" mesh="link1" name="link1_collision"/>
          <body name="link2" pos="0 0 0" quat="0.707107 -0.707107 0 0">
            <inertial pos="-0.003141 0.02872 0.003495" mass="0.647" fullinertia="7.9620e-03 2.8110e-02 2.5995e-02 -3.9250e-03 1.0254e-02 7.0400e-04" />
            <joint name="joint2" pos="0 0 0" axis="0 0 1" limited="true" range="-1.7628 1.7628" damping="0.1"/>
            <geom type="mesh" contype="0" conaffinity="0" group="1" mesh="link2_vis" name="link2_visual" rgba="1 1 1 1" />
            <!-- <geom type="mesh" group="0" mesh="link2" name="link2_collision" mass="2.73046"/> -->
            <geom type="mesh" group="0" mesh="link2" name="link2_collision"/>
            <body name="link3" pos="0 -0.316 0" quat="0.707107 0.707107 0 0">
              <inertial pos="2.7518e-02 3.9252e-02 -6.6502e-02" mass="3.228604" fullinertia="3.7242e-02 3.6155e-02 1.0830e-02 -4.7610e-03 -1.1396e-02 -1.2805e-02" />
              <joint name="joint3" pos="0 0 0" axis="0 0 1" limited="true" range="-2.8973 2.8973" damping="0.1"/>
              <geom type="mesh" contype="0" conaffinity="0" group="1" mesh="link3_vis" name="link3_visual" rgba="1 1 1 1" />
              <!-- <geom type="mesh" group="0" mesh="link3" name="link3_collision" mass="2.04104"/> -->
              <geom type="mesh" group="0" mesh="link3" name="link3_collision"/>
              <body name="link4" pos="0.0825 0 0" quat="0.707107 0.707107 0 0">
                <inertial pos="-5.317e-02 1.04419e-01 2.7454e-02" mass="3.587895" fullinertia="2.5853e-02 1.9552e-02 2.8323e-02 7.7960e-03 -1.3320e-03 8.6410e-03" />
                <joint name="joint4" pos="0 0 0" axis="0 0 1" limited="true" range="-3.0718 -0.0698" damping="0.1"/>
                <geom type="mesh" contype="0" conaffinity="0" group="1" mesh="link4_vis" name="link4_visual" rgba="1 1 1 1" />
                <!-- <geom type="mesh" group="0" mesh="link4" name="link4_collision" mass="2.08129"/> -->
                <geom type="mesh" group="0" mesh="link4" name="link4_collision"/>
                <body name="link5" pos="-0.0825 0.384 0" quat="0.707107 -0.707107 0 0">
                  <inertial pos="-1.1953e-02 4.1065e-02 -3.8437e-02" mass="1.225946" fullinertia="3.5549e-02 2.9474e-02 8.6270e-03 -2.1170e-03 -4.0370e-03 2.2900e-04" />
                  <joint name="joint5" pos="0 0 0" axis="0 0 1" limited="true" range="-2.8973 2.8973" damping="0.1"/>
                  <geom type="mesh" contype="0" conaffinity="0" group="1" mesh="link5_vis" name="link5_visual" rgba="1 1 1 1" />
                  <!-- <geom type="mesh" group="0" mesh="link5" name="link5_collision" mass="3.00049"/> -->
                  <geom type="mesh" group="0" mesh="link5" name="link5_collision"/>
                  <body name="link6" pos="0 0 0" quat="0.707107 0.707107 0 0">
                    <inertial pos="6.0149e-02 -1.4117e-02 -1.0517e-02" mass="1.666555" fullinertia="1.9640e-03 4.3540e-03 5.4330e-03 1.0900e-04 -1.1580e-03 3.4100e-04" />
                    <joint name="joint6" pos="0 0 0" axis="0 0 1" limited="true" range="-0.0175 3.7525" damping="0.01"/>
                    <geom type="mesh" contype="0" conaffinity="0" group="1" mesh="link6_vis" name="link6_visual" rgba="1 1 1 1" />
                    <!-- <geom type="mesh" group="0" mesh="link6" name="link6_collision" mass="1.3235"/> -->
                    <geom type="mesh" group="0" mesh="link6" name="link6_collision"/>
                    <body name="link7" pos="0.088 0 0" quat="0.707107 0.707107 0 0">
                      <inertial pos="1.0517e-02 -4.252e-03 6.1597e-02" mass="7.35522e-01" fullinertia="1.2516e-02 1.0027e-02 4.8150e-03 -4.2800e-04 -1.1960e-03 -7.4100e-04" />
                      <joint name="joint7" pos="0 0 0" axis="0 0 1" limited="true" range="-2.8973 2.8973" damping="0.01"/>
                      <geom type="mesh" contype="0" conaffinity="0" group="1" mesh="link7_vis" name="link7_visual" rgba="1. 1. 1. 1." />
                      <!-- <geom type="mesh" group="0" mesh="link7" name="link7_collision" mass="0.2"/> -->
                      <geom type="mesh" group="0" mesh="link7" name="link7_collision"/>
                      <!-- rotate 135deg to align physically to the tool-->
                      <body name="right_hand" pos="0 0 0.107" quat="0.924 0 0 -0.383">
                        <inertial pos="0 0 0" mass="0.5" diaginertia="0.05 0.05 0.05" />
                        <!-- This camera points out from the eef. -->
                        <camera mode="fixed" name="eye_in_hand" pos="0.05 0 0" quat="0 0.707108 0.707108 0" fovy="75"/>
                        <!-- to add gripper -->
                        <site name="eef_site" pos="0 0 0.1034" size="0.01 0.01 0.01" rgba="0 0 0 0" type="sphere" group="1" />
                        <site name="sensor_site" pos="0 0 0" size="0.01 0.01 0.01" rgba="0 0 0 0" type="sphere" group="1" />
                      </body>
                    </body>
                  </body>
                </body>
              </body>
            </body>
          </body>
        </body>
      </body>
    </body>
  </worldbody>
  <sensor>
    <torque name="torque_rh" site="sensor_site" />
    <force name="force_rh" site="sensor_site" />
  </sensor>
</mujoco>
